[2024-03-01 11:20:39,821] {taskinstance.py:1159} INFO - Dependencies all met for <TaskInstance: dados_climaticos.cria_pasta scheduled__2023-05-15T00:00:00+00:00 [queued]>
[2024-03-01 11:20:39,827] {taskinstance.py:1159} INFO - Dependencies all met for <TaskInstance: dados_climaticos.cria_pasta scheduled__2023-05-15T00:00:00+00:00 [queued]>
[2024-03-01 11:20:39,827] {taskinstance.py:1356} INFO - 
--------------------------------------------------------------------------------
[2024-03-01 11:20:39,827] {taskinstance.py:1357} INFO - Starting attempt 1 of 1
[2024-03-01 11:20:39,827] {taskinstance.py:1358} INFO - 
--------------------------------------------------------------------------------
[2024-03-01 11:20:39,842] {taskinstance.py:1377} INFO - Executing <Task(BashOperator): cria_pasta> on 2023-05-15 00:00:00+00:00
[2024-03-01 11:20:39,846] {standard_task_runner.py:52} INFO - Started process 20678 to run task
[2024-03-01 11:20:39,847] {standard_task_runner.py:79} INFO - Running: ['airflow', 'tasks', 'run', 'dados_climaticos', 'cria_pasta', 'scheduled__2023-05-15T00:00:00+00:00', '--job-id', '50', '--raw', '--subdir', 'DAGS_FOLDER/dados_climaticos.py', '--cfg-path', '/tmp/tmpn3hd8t8b', '--error-file', '/tmp/tmpbzm3fbqo']
[2024-03-01 11:20:39,848] {standard_task_runner.py:80} INFO - Job 50: Subtask cria_pasta
[2024-03-01 11:20:39,878] {task_command.py:370} INFO - Running <TaskInstance: dados_climaticos.cria_pasta scheduled__2023-05-15T00:00:00+00:00 [running]> on host BITL0401.
[2024-03-01 11:20:39,900] {taskinstance.py:1889} ERROR - Task failed with exception
Traceback (most recent call last):
  File "/home/luan/Documents/airflowalura/venv/lib/python3.9/site-packages/airflow/models/taskinstance.py", line 1451, in _run_raw_task
    self._execute_task_with_callbacks(context, test_mode)
  File "/home/luan/Documents/airflowalura/venv/lib/python3.9/site-packages/airflow/models/taskinstance.py", line 1555, in _execute_task_with_callbacks
    task_orig = self.render_templates(context=context)
  File "/home/luan/Documents/airflowalura/venv/lib/python3.9/site-packages/airflow/models/taskinstance.py", line 2212, in render_templates
    rendered_task = self.task.render_template_fields(context)
  File "/home/luan/Documents/airflowalura/venv/lib/python3.9/site-packages/airflow/models/baseoperator.py", line 1185, in render_template_fields
    self._do_render_template_fields(self, self.template_fields, context, jinja_env, set())
  File "/home/luan/Documents/airflowalura/venv/lib/python3.9/site-packages/airflow/utils/session.py", line 71, in wrapper
    return func(*args, session=session, **kwargs)
  File "/home/luan/Documents/airflowalura/venv/lib/python3.9/site-packages/airflow/models/abstractoperator.py", line 344, in _do_render_template_fields
    rendered_content = self.render_template(
  File "/home/luan/Documents/airflowalura/venv/lib/python3.9/site-packages/airflow/models/abstractoperator.py", line 391, in render_template
    return render_template_to_string(template, context)
  File "/home/luan/Documents/airflowalura/venv/lib/python3.9/site-packages/airflow/utils/helpers.py", line 296, in render_template_to_string
    return render_template(template, context, native=False)
  File "/home/luan/Documents/airflowalura/venv/lib/python3.9/site-packages/airflow/utils/helpers.py", line 291, in render_template
    return "".join(nodes)
  File "<template>", line 13, in root
  File "/home/luan/Documents/airflowalura/venv/lib/python3.9/site-packages/jinja2/sandbox.py", line 391, in call
    if not __self.is_safe_callable(__obj):
  File "/home/luan/Documents/airflowalura/venv/lib/python3.9/site-packages/jinja2/sandbox.py", line 275, in is_safe_callable
    getattr(obj, "unsafe_callable", False) or getattr(obj, "alters_data", False)
  File "/home/luan/Documents/airflowalura/venv/lib/python3.9/site-packages/jinja2/runtime.py", line 910, in __getattr__
    return self._fail_with_undefined_error()
  File "/home/luan/Documents/airflowalura/venv/lib/python3.9/site-packages/jinja2/runtime.py", line 903, in _fail_with_undefined_error
    raise self._undefined_exception(self._undefined_message)
jinja2.exceptions.UndefinedError: 'pendulum.datetime.DateTime object' has no attribute 'srtftime'
[2024-03-01 11:20:39,904] {taskinstance.py:1395} INFO - Marking task as FAILED. dag_id=dados_climaticos, task_id=cria_pasta, execution_date=20230515T000000, start_date=20240301T142039, end_date=20240301T142039
[2024-03-01 11:20:39,916] {standard_task_runner.py:92} ERROR - Failed to execute job 50 for task cria_pasta ('pendulum.datetime.DateTime object' has no attribute 'srtftime'; 20678)
[2024-03-01 11:20:39,941] {local_task_job.py:156} INFO - Task exited with return code 1
[2024-03-01 11:20:39,971] {local_task_job.py:273} INFO - 0 downstream tasks scheduled from follow-on schedule check
