[2024-03-01 11:21:35,353] {taskinstance.py:1159} INFO - Dependencies all met for <TaskInstance: dados_climaticos.extrai_dados scheduled__2023-10-30T00:00:00+00:00 [queued]>
[2024-03-01 11:21:35,358] {taskinstance.py:1159} INFO - Dependencies all met for <TaskInstance: dados_climaticos.extrai_dados scheduled__2023-10-30T00:00:00+00:00 [queued]>
[2024-03-01 11:21:35,358] {taskinstance.py:1356} INFO - 
--------------------------------------------------------------------------------
[2024-03-01 11:21:35,358] {taskinstance.py:1357} INFO - Starting attempt 1 of 1
[2024-03-01 11:21:35,358] {taskinstance.py:1358} INFO - 
--------------------------------------------------------------------------------
[2024-03-01 11:21:35,375] {taskinstance.py:1377} INFO - Executing <Task(PythonOperator): extrai_dados> on 2023-10-30 00:00:00+00:00
[2024-03-01 11:21:35,378] {standard_task_runner.py:52} INFO - Started process 21232 to run task
[2024-03-01 11:21:35,381] {standard_task_runner.py:79} INFO - Running: ['airflow', 'tasks', 'run', 'dados_climaticos', 'extrai_dados', 'scheduled__2023-10-30T00:00:00+00:00', '--job-id', '76', '--raw', '--subdir', 'DAGS_FOLDER/dados_climaticos.py', '--cfg-path', '/tmp/tmpizbjfakz', '--error-file', '/tmp/tmpiaiq0f7x']
[2024-03-01 11:21:35,381] {standard_task_runner.py:80} INFO - Job 76: Subtask extrai_dados
[2024-03-01 11:21:35,412] {task_command.py:370} INFO - Running <TaskInstance: dados_climaticos.extrai_dados scheduled__2023-10-30T00:00:00+00:00 [running]> on host BITL0401.
[2024-03-01 11:21:35,461] {taskinstance.py:1569} INFO - Exporting the following env vars:
AIRFLOW_CTX_DAG_OWNER=airflow
AIRFLOW_CTX_DAG_ID=dados_climaticos
AIRFLOW_CTX_TASK_ID=extrai_dados
AIRFLOW_CTX_EXECUTION_DATE=2023-10-30T00:00:00+00:00
AIRFLOW_CTX_TRY_NUMBER=1
AIRFLOW_CTX_DAG_RUN_ID=scheduled__2023-10-30T00:00:00+00:00
[2024-03-01 11:21:36,122] {taskinstance.py:1889} ERROR - Task failed with exception
Traceback (most recent call last):
  File "/home/luan/Documents/airflowalura/venv/lib/python3.9/site-packages/airflow/operators/python.py", line 171, in execute
    return_value = self.execute_callable()
  File "/home/luan/Documents/airflowalura/venv/lib/python3.9/site-packages/airflow/operators/python.py", line 189, in execute_callable
    return self.python_callable(*self.op_args, **self.op_kwargs)
  File "/home/luan/Documents/airflowalura/dags/dados_climaticos.py", line 33, in extrai_dados
    dados.to_csv(file_path + 'dados_brutos.csv')
  File "/home/luan/Documents/airflowalura/venv/lib/python3.9/site-packages/pandas/util/_decorators.py", line 333, in wrapper
    return func(*args, **kwargs)
  File "/home/luan/Documents/airflowalura/venv/lib/python3.9/site-packages/pandas/core/generic.py", line 3964, in to_csv
    return DataFrameRenderer(formatter).to_csv(
  File "/home/luan/Documents/airflowalura/venv/lib/python3.9/site-packages/pandas/io/formats/format.py", line 1014, in to_csv
    csv_formatter.save()
  File "/home/luan/Documents/airflowalura/venv/lib/python3.9/site-packages/pandas/io/formats/csvs.py", line 251, in save
    with get_handle(
  File "/home/luan/Documents/airflowalura/venv/lib/python3.9/site-packages/pandas/io/common.py", line 749, in get_handle
    check_parent_directory(str(handle))
  File "/home/luan/Documents/airflowalura/venv/lib/python3.9/site-packages/pandas/io/common.py", line 616, in check_parent_directory
    raise OSError(rf"Cannot save file into a non-existent directory: '{parent}'")
OSError: Cannot save file into a non-existent directory: '/home/luan/Documents/datapipeline/semana=2023-11-06'
[2024-03-01 11:21:36,126] {taskinstance.py:1395} INFO - Marking task as FAILED. dag_id=dados_climaticos, task_id=extrai_dados, execution_date=20231030T000000, start_date=20240301T142135, end_date=20240301T142136
[2024-03-01 11:21:36,142] {standard_task_runner.py:92} ERROR - Failed to execute job 76 for task extrai_dados (Cannot save file into a non-existent directory: '/home/luan/Documents/datapipeline/semana=2023-11-06'; 21232)
[2024-03-01 11:21:36,158] {local_task_job.py:156} INFO - Task exited with return code 1
[2024-03-01 11:21:36,170] {local_task_job.py:273} INFO - 0 downstream tasks scheduled from follow-on schedule check
