[2024-03-01 11:19:49,770] {taskinstance.py:1159} INFO - Dependencies all met for <TaskInstance: dados_climaticos.cria_pasta scheduled__2022-12-05T00:00:00+00:00 [queued]>
[2024-03-01 11:19:49,775] {taskinstance.py:1159} INFO - Dependencies all met for <TaskInstance: dados_climaticos.cria_pasta scheduled__2022-12-05T00:00:00+00:00 [queued]>
[2024-03-01 11:19:49,775] {taskinstance.py:1356} INFO - 
--------------------------------------------------------------------------------
[2024-03-01 11:19:49,775] {taskinstance.py:1357} INFO - Starting attempt 1 of 1
[2024-03-01 11:19:49,775] {taskinstance.py:1358} INFO - 
--------------------------------------------------------------------------------
[2024-03-01 11:19:49,791] {taskinstance.py:1377} INFO - Executing <Task(BashOperator): cria_pasta> on 2022-12-05 00:00:00+00:00
[2024-03-01 11:19:49,796] {standard_task_runner.py:52} INFO - Started process 20201 to run task
[2024-03-01 11:19:49,798] {standard_task_runner.py:79} INFO - Running: ['airflow', 'tasks', 'run', 'dados_climaticos', 'cria_pasta', 'scheduled__2022-12-05T00:00:00+00:00', '--job-id', '27', '--raw', '--subdir', 'DAGS_FOLDER/dados_climaticos.py', '--cfg-path', '/tmp/tmp8fnkaye0', '--error-file', '/tmp/tmp3g5508ey']
[2024-03-01 11:19:49,799] {standard_task_runner.py:80} INFO - Job 27: Subtask cria_pasta
[2024-03-01 11:19:49,836] {task_command.py:370} INFO - Running <TaskInstance: dados_climaticos.cria_pasta scheduled__2022-12-05T00:00:00+00:00 [running]> on host BITL0401.
[2024-03-01 11:19:49,860] {taskinstance.py:1889} ERROR - Task failed with exception
Traceback (most recent call last):
  File "/home/luan/Documents/airflowalura/venv/lib/python3.9/site-packages/airflow/models/taskinstance.py", line 1451, in _run_raw_task
    self._execute_task_with_callbacks(context, test_mode)
  File "/home/luan/Documents/airflowalura/venv/lib/python3.9/site-packages/airflow/models/taskinstance.py", line 1555, in _execute_task_with_callbacks
    task_orig = self.render_templates(context=context)
  File "/home/luan/Documents/airflowalura/venv/lib/python3.9/site-packages/airflow/models/taskinstance.py", line 2212, in render_templates
    rendered_task = self.task.render_template_fields(context)
  File "/home/luan/Documents/airflowalura/venv/lib/python3.9/site-packages/airflow/models/baseoperator.py", line 1185, in render_template_fields
    self._do_render_template_fields(self, self.template_fields, context, jinja_env, set())
  File "/home/luan/Documents/airflowalura/venv/lib/python3.9/site-packages/airflow/utils/session.py", line 71, in wrapper
    return func(*args, session=session, **kwargs)
  File "/home/luan/Documents/airflowalura/venv/lib/python3.9/site-packages/airflow/models/abstractoperator.py", line 344, in _do_render_template_fields
    rendered_content = self.render_template(
  File "/home/luan/Documents/airflowalura/venv/lib/python3.9/site-packages/airflow/models/abstractoperator.py", line 391, in render_template
    return render_template_to_string(template, context)
  File "/home/luan/Documents/airflowalura/venv/lib/python3.9/site-packages/airflow/utils/helpers.py", line 296, in render_template_to_string
    return render_template(template, context, native=False)
  File "/home/luan/Documents/airflowalura/venv/lib/python3.9/site-packages/airflow/utils/helpers.py", line 291, in render_template
    return "".join(nodes)
  File "<template>", line 13, in root
  File "/home/luan/Documents/airflowalura/venv/lib/python3.9/site-packages/jinja2/sandbox.py", line 391, in call
    if not __self.is_safe_callable(__obj):
  File "/home/luan/Documents/airflowalura/venv/lib/python3.9/site-packages/jinja2/sandbox.py", line 275, in is_safe_callable
    getattr(obj, "unsafe_callable", False) or getattr(obj, "alters_data", False)
  File "/home/luan/Documents/airflowalura/venv/lib/python3.9/site-packages/jinja2/runtime.py", line 910, in __getattr__
    return self._fail_with_undefined_error()
  File "/home/luan/Documents/airflowalura/venv/lib/python3.9/site-packages/jinja2/runtime.py", line 903, in _fail_with_undefined_error
    raise self._undefined_exception(self._undefined_message)
jinja2.exceptions.UndefinedError: 'pendulum.datetime.DateTime object' has no attribute 'srtftime'
[2024-03-01 11:19:49,863] {taskinstance.py:1395} INFO - Marking task as FAILED. dag_id=dados_climaticos, task_id=cria_pasta, execution_date=20221205T000000, start_date=20240301T141949, end_date=20240301T141949
[2024-03-01 11:19:49,876] {standard_task_runner.py:92} ERROR - Failed to execute job 27 for task cria_pasta ('pendulum.datetime.DateTime object' has no attribute 'srtftime'; 20201)
[2024-03-01 11:19:49,892] {local_task_job.py:156} INFO - Task exited with return code 1
[2024-03-01 11:19:49,928] {local_task_job.py:273} INFO - 0 downstream tasks scheduled from follow-on schedule check
[2024-03-01 11:22:57,890] {taskinstance.py:1159} INFO - Dependencies all met for <TaskInstance: dados_climaticos.cria_pasta scheduled__2022-12-05T00:00:00+00:00 [queued]>
[2024-03-01 11:22:57,897] {taskinstance.py:1159} INFO - Dependencies all met for <TaskInstance: dados_climaticos.cria_pasta scheduled__2022-12-05T00:00:00+00:00 [queued]>
[2024-03-01 11:22:57,897] {taskinstance.py:1356} INFO - 
--------------------------------------------------------------------------------
[2024-03-01 11:22:57,897] {taskinstance.py:1357} INFO - Starting attempt 1 of 1
[2024-03-01 11:22:57,897] {taskinstance.py:1358} INFO - 
--------------------------------------------------------------------------------
[2024-03-01 11:22:57,914] {taskinstance.py:1377} INFO - Executing <Task(BashOperator): cria_pasta> on 2022-12-05 00:00:00+00:00
[2024-03-01 11:22:57,918] {standard_task_runner.py:52} INFO - Started process 21932 to run task
[2024-03-01 11:22:57,920] {standard_task_runner.py:79} INFO - Running: ['airflow', 'tasks', 'run', 'dados_climaticos', 'cria_pasta', 'scheduled__2022-12-05T00:00:00+00:00', '--job-id', '41', '--raw', '--subdir', 'DAGS_FOLDER/dados_climaticos.py', '--cfg-path', '/tmp/tmp66x8y05v', '--error-file', '/tmp/tmpou5j12l5']
[2024-03-01 11:22:57,921] {standard_task_runner.py:80} INFO - Job 41: Subtask cria_pasta
[2024-03-01 11:22:57,952] {task_command.py:370} INFO - Running <TaskInstance: dados_climaticos.cria_pasta scheduled__2022-12-05T00:00:00+00:00 [running]> on host BITL0401.
[2024-03-01 11:22:57,998] {taskinstance.py:1569} INFO - Exporting the following env vars:
AIRFLOW_CTX_DAG_OWNER=airflow
AIRFLOW_CTX_DAG_ID=dados_climaticos
AIRFLOW_CTX_TASK_ID=cria_pasta
AIRFLOW_CTX_EXECUTION_DATE=2022-12-05T00:00:00+00:00
AIRFLOW_CTX_TRY_NUMBER=1
AIRFLOW_CTX_DAG_RUN_ID=scheduled__2022-12-05T00:00:00+00:00
[2024-03-01 11:22:57,998] {subprocess.py:62} INFO - Tmp dir root location: 
 /tmp
[2024-03-01 11:22:57,999] {subprocess.py:74} INFO - Running command: ['bash', '-c', 'mkdir -p "/home/luan/Documents/airflowalura/semana=2022-12-12"']
[2024-03-01 11:22:58,005] {subprocess.py:85} INFO - Output:
[2024-03-01 11:22:58,006] {subprocess.py:96} INFO - Command exited with return code 0
[2024-03-01 11:22:58,025] {taskinstance.py:1395} INFO - Marking task as SUCCESS. dag_id=dados_climaticos, task_id=cria_pasta, execution_date=20221205T000000, start_date=20240301T142257, end_date=20240301T142258
[2024-03-01 11:22:58,054] {local_task_job.py:156} INFO - Task exited with return code 0
[2024-03-01 11:22:58,077] {local_task_job.py:273} INFO - 1 downstream tasks scheduled from follow-on schedule check
